Workbook
Name AA: Data!$A$1
Name ReportingNames: Data!$A$2:$A$13

Sheet Executive Summary
A1: FreshMart Monthly Trading Performance Pack
A2: Reporting Month | B2: 45992
A4: KPI | B4: Current Month | C4: Previous Month | D4: MoM % | E4: Target | F4: Vs Target
A5: Net Sales | B5: =_xlfn.XLOOKUP( TEXT($B$2,"yyyy-mm"), tblCompanyMonthly[month_year], tblCompanyMonthly[net_sales], "" ) -> 433925.11 | C5: =_xlfn.XLOOKUP( TEXT(EDATE($B$2,-1),"yyyy-mm"), tblCompanyMonthly[month_year], tblCompanyMonthly[net_sales], "" ) -> 416804.93 | D5: =_xlfn.XLOOKUP( TEXT($B$2,"yyyy-mm"), tblCompanyMonthly[month_year], tblCompanyMonthly[sales_mom_pct], "" ) -> 4.11 | E5: =_xlfn.XLOOKUP( TEXT($B$2,"yyyy-mm"), tblCompanyMonthly[month_year], tblCompanyMonthly[sales_target], "" ) -> 426923.77 | F5: =_xlfn.XLOOKUP( TEXT($B$2,"yyyy-mm"), tblCompanyMonthly[month_year], tblCompanyMonthly[sales_vs_target], "" ) -> 7001.34
A6: Transactions | B6: =_xlfn.XLOOKUP( TEXT($B$2,"yyyy-mm"), tblCompanyMonthly[month_year], tblCompanyMonthly[transactions], "" ) -> 10404 | C6: =_xlfn.XLOOKUP( TEXT(EDATE($B$2,-1),"yyyy-mm"), tblCompanyMonthly[month_year], tblCompanyMonthly[transactions], "" ) -> 10110 | D6: =_xlfn.XLOOKUP( TEXT($B$2,"yyyy-mm"), tblCompanyMonthly[month_year], tblCompanyMonthly[transactions_mom_pct], "" ) -> 2.91 | E6: — | F6: —
A7: ATV | B7: =_xlfn.XLOOKUP(TEXT($B$2,"yyyy-mm"),tblCompanyMonthly[month_year],tblCompanyMonthly[avg_transaction_value],"") -> 41.71 | C7: =_xlfn.XLOOKUP(TEXT(EDATE($B$2,-1),"yyyy-mm"),tblCompanyMonthly[month_year],tblCompanyMonthly[avg_transaction_value],"") -> 41.23 | D7: =_xlfn.XLOOKUP(TEXT($B$2,"yyyy-mm"),tblCompanyMonthly[month_year],tblCompanyMonthly[atv_mom_pct],"") -> 1.16
A8: UPT | B8: =_xlfn.XLOOKUP(TEXT($B$2,"yyyy-mm"),tblCompanyMonthly[month_year],tblCompanyMonthly[units_per_transaction],"") -> 5.17 | C8: =_xlfn.XLOOKUP(TEXT(EDATE($B$2,-1),"yyyy-mm"),tblCompanyMonthly[month_year],tblCompanyMonthly[units_per_transaction],"") -> 5.15 | D8: =_xlfn.XLOOKUP(TEXT($B$2,"yyyy-mm"),tblCompanyMonthly[month_year],tblCompanyMonthly[upt_mom_pct],"") -> 0.39
A9: ASP | B9: =_xlfn.XLOOKUP(TEXT($B$2,"yyyy-mm"),tblCompanyMonthly[month_year],tblCompanyMonthly[avg_selling_price],"") -> 8.07 | C9: =_xlfn.XLOOKUP(TEXT(EDATE($B$2,-1),"yyyy-mm"),tblCompanyMonthly[month_year],tblCompanyMonthly[avg_selling_price],"") -> 8.01 | D9: =_xlfn.XLOOKUP(TEXT($B$2,"yyyy-mm"),tblCompanyMonthly[month_year],tblCompanyMonthly[asp_mom_pct],"") -> 0.75
A11: YTD Net Sales | B11: YTD Target | C11: Variance to Target | D11: Target Achievement
A12: =_xlfn.XLOOKUP( TEXT($B$2,"yyyy-mm"), tblCompanyMonthly[month_year], tblCompanyMonthly[ytd_net_sales], "" ) -> 4745313.9 | B12: =_xlfn.XLOOKUP( TEXT($B$2,"yyyy-mm"), tblCompanyMonthly[month_year], tblCompanyMonthly[ytd_sales_target], "" ) -> 4712471.6 | C12: =_xlfn.XLOOKUP( TEXT($B$2,"yyyy-mm"), tblCompanyMonthly[month_year], tblCompanyMonthly[ytd_sales_vs_target], "" ) -> 32842.3 | D12: =_xlfn.XLOOKUP( TEXT($B$2,"yyyy-mm"), tblCompanyMonthly[month_year], tblCompanyMonthly[ytd_target_achievement_pct], "" ) -> 100.7
A14: Sales Trend
A29: Top Target Achievers | D29: Stores Requiring Attention
A30: Stores | B30: Target Achievement | D30: Store | E30: MoM % | F30: Target %
A31: ='Store Performance'!A33 -> FreshMart London 06 | B31: ='Store Performance'!B33 -> 106.03 | D31: ='Store Performance'!D33 -> No stores flagged
A32: ='Store Performance'!A34 -> FreshMart North West 15 | B32: ='Store Performance'!B34 -> 106.03
A33: ='Store Performance'!A35 -> FreshMart South East 07 | B33: ='Store Performance'!B35 -> 103.48
A36: Area | B36: Management Commentary
A37: Trading | B37: December Net Sales increased 4.1% MoM, alongside a 2.9% increase in transactions. ATV also increased 1.2%, supported by modest improvements in both units per transaction and average selling price, indicating growth came from a combination of higher transaction volume and slightly stronger basket value.
A38: Target / YTD | B38: December Sales exceeded target by £7.0k, achieving 101.6% of monthly plan. Full-year Sales finished £32.8k above target, with YTD target achievement of 100.7%.
A39: Store Performance | B39: No stores met the current dual-trigger management-attention rule. However, FreshMart London 21 declined 10.2% MoM despite remaining above target, while FreshMart Midlands 14 declined 7.1% and achieved only 96.5% of target. Both warrant review to understand the decline.

Sheet Store Performance
A1: FreshMart Store Performance
A2: Reporting Month | B2: ='Executive Summary'!B2 -> 45992
A4: Store | B4: Format | C4: Region | D4: Net Sales | E4: MoM % | F4: Sales Target | G4: Target Achievement % | H4: Variance to Target | I4: Target Rank | J4: Management Attention
A5: {=_xlfn.UNIQUE(_xlfn._xlws.FILTER(tblStoreMonthly[store_name],tblStoreMonthly[month_year]=TEXT($B$2,"yyyy-mm")))} -> FreshMart London 01 | B5: =_xlfn.XLOOKUP(A5,tblStoreMonthly[store_name],tblStoreMonthly[store_format]) -> Supermarket | C5: =_xlfn.XLOOKUP(A5,tblStoreMonthly[store_name],tblStoreMonthly[region]) -> London | D5: {=_xlfn.XLOOKUP(1,(tblStoreMonthly[month_year]=TEXT($B$2,"yyyy-mm"))*(tblStoreMonthly[store_name]=A5),tblStoreMonthly[net_sales])} -> 15619.51 | E5: {=_xlfn.XLOOKUP(1,(tblStoreMonthly[month_year]=TEXT($B$2,"yyyy-mm"))*(tblStoreMonthly[store_name]=A5),tblStoreMonthly[mom_sales_growth_pct])} -> 3.4 | F5: {=_xlfn.XLOOKUP(1,(tblStoreMonthly[month_year]=TEXT($B$2,"yyyy-mm"))*(tblStoreMonthly[store_name]=A5),tblStoreMonthly[sales_target])} -> 15967.3 | G5: {=_xlfn.XLOOKUP( 1, (tblStoreMonthly[month_year]=TEXT($B$2,"yyyy-mm"))* (tblStoreMonthly[store_name]=A5), tblStoreMonthly[target_achievement_pct], "" )} -> 97.82 | H5: {=_xlfn.XLOOKUP( 1, (tblStoreMonthly[month_year]=TEXT($B$2,"yyyy-mm"))* (tblStoreMonthly[store_name]=A5), tblStoreMonthly[sales_vs_target], "" )} -> -347.79 | I5: =_xlfn.RANK.EQ(G5,$G$5:$G$29,0) -> 21 | J5: =IF( AND(E5<-5,G5<95), "Investigate", "")
A6: FreshMart South East 02 | B6: =_xlfn.XLOOKUP(A6,tblStoreMonthly[store_name],tblStoreMonthly[store_format]) -> Supermarket | C6: =_xlfn.XLOOKUP(A6,tblStoreMonthly[store_name],tblStoreMonthly[region]) -> South East | D6: {=_xlfn.XLOOKUP(1,(tblStoreMonthly[month_year]=TEXT($B$2,"yyyy-mm"))*(tblStoreMonthly[store_name]=A6),tblStoreMonthly[net_sales])} -> 16483.11 | E6: {=_xlfn.XLOOKUP(1,(tblStoreMonthly[month_year]=TEXT($B$2,"yyyy-mm"))*(tblStoreMonthly[store_name]=A6),tblStoreMonthly[mom_sales_growth_pct])} -> 8.82 | F6: {=_xlfn.XLOOKUP(1,(tblStoreMonthly[month_year]=TEXT($B$2,"yyyy-mm"))*(tblStoreMonthly[store_name]=A6),tblStoreMonthly[sales_target])} -> 16554.33 | G6: {=_xlfn.XLOOKUP( 1, (tblStoreMonthly[month_year]=TEXT($B$2,"yyyy-mm"))* (tblStoreMonthly[store_name]=A6), tblStoreMonthly[target_achievement_pct], "" )} -> 99.57 | H6: {=_xlfn.XLOOKUP( 1, (tblStoreMonthly[month_year]=TEXT($B$2,"yyyy-mm"))* (tblStoreMonthly[store_name]=A6), tblStoreMonthly[sales_vs_target], "" )} -> -71.22 | I6: =_xlfn.RANK.EQ(G6,$G$5:$G$29,0) -> 17 | J6: =IF( AND(E6<-5,G6<95), "Investigate", "")
A7: FreshMart South West 03 | B7: =_xlfn.XLOOKUP(A7,tblStoreMonthly[store_name],tblStoreMonthly[store_format]) -> Supermarket | C7: =_xlfn.XLOOKUP(A7,tblStoreMonthly[store_name],tblStoreMonthly[region]) -> South West | D7: {=_xlfn.XLOOKUP(1,(tblStoreMonthly[month_year]=TEXT($B$2,"yyyy-mm"))*(tblStoreMonthly[store_name]=A7),tblStoreMonthly[net_sales])} -> 16656.28 | E7: {=_xlfn.XLOOKUP(1,(tblStoreMonthly[month_year]=TEXT($B$2,"yyyy-mm"))*(tblStoreMonthly[store_name]=A7),tblStoreMonthly[mom_sales_growth_pct])} -> -0.56 | F7: {=_xlfn.XLOOKUP(1,(tblStoreMonthly[month_year]=TEXT($B$2,"yyyy-mm"))*(tblStoreMonthly[store_name]=A7),tblStoreMonthly[sales_target])} -> 16281.6 | G7: {=_xlfn.XLOOKUP( 1, (tblStoreMonthly[month_year]=TEXT($B$2,"yyyy-mm"))* (tblStoreMonthly[store_name]=A7), tblStoreMonthly[target_achievement_pct], "" )} -> 102.3 | H7: {=_xlfn.XLOOKUP( 1, (tblStoreMonthly[month_year]=TEXT($B$2,"yyyy-mm"))* (tblStoreMonthly[store_name]=A7), tblStoreMonthly[sales_vs_target], "" )} -> 374.68 | I7: =_xlfn.RANK.EQ(G7,$G$5:$G$29,0) -> 14 | J7: =IF( AND(E7<-5,G7<95), "Investigate", "")
A8: FreshMart Midlands 04 | B8: =_xlfn.XLOOKUP(A8,tblStoreMonthly[store_name],tblStoreMonthly[store_format]) -> Supermarket | C8: =_xlfn.XLOOKUP(A8,tblStoreMonthly[store_name],tblStoreMonthly[region]) -> Midlands | D8: {=_xlfn.XLOOKUP(1,(tblStoreMonthly[month_year]=TEXT($B$2,"yyyy-mm"))*(tblStoreMonthly[store_name]=A8),tblStoreMonthly[net_sales])} -> 16617.28 | E8: {=_xlfn.XLOOKUP(1,(tblStoreMonthly[month_year]=TEXT($B$2,"yyyy-mm"))*(tblStoreMonthly[store_name]=A8),tblStoreMonthly[mom_sales_growth_pct])} -> 5.57 | F8: {=_xlfn.XLOOKUP(1,(tblStoreMonthly[month_year]=TEXT($B$2,"yyyy-mm"))*(tblStoreMonthly[store_name]=A8),tblStoreMonthly[sales_target])} -> 16127.97 | G8: {=_xlfn.XLOOKUP( 1, (tblStoreMonthly[month_year]=TEXT($B$2,"yyyy-mm"))* (tblStoreMonthly[store_name]=A8), tblStoreMonthly[target_achievement_pct], "" )} -> 103.03 | H8: {=_xlfn.XLOOKUP( 1, (tblStoreMonthly[month_year]=TEXT($B$2,"yyyy-mm"))* (tblStoreMonthly[store_name]=A8), tblStoreMonthly[sales_vs_target], "" )} -> 489.31 | I8: =_xlfn.RANK.EQ(G8,$G$5:$G$29,0) -> 11 | J8: =IF( AND(E8<-5,G8<95), "Investigate", "")
A9: FreshMart North West 05 | B9: =_xlfn.XLOOKUP(A9,tblStoreMonthly[store_name],tblStoreMonthly[store_format]) -> Supermarket | C9: =_xlfn.XLOOKUP(A9,tblStoreMonthly[store_name],tblStoreMonthly[region]) -> North West | D9: {=_xlfn.XLOOKUP(1,(tblStoreMonthly[month_year]=TEXT($B$2,"yyyy-mm"))*(tblStoreMonthly[store_name]=A9),tblStoreMonthly[net_sales])} -> 15932.61 | E9: {=_xlfn.XLOOKUP(1,(tblStoreMonthly[month_year]=TEXT($B$2,"yyyy-mm"))*(tblStoreMonthly[store_name]=A9),tblStoreMonthly[mom_sales_growth_pct])} -> 10.72 | F9: {=_xlfn.XLOOKUP(1,(tblStoreMonthly[month_year]=TEXT($B$2,"yyyy-mm"))*(tblStoreMonthly[store_name]=A9),tblStoreMonthly[sales_target])} -> 16507.13 | G9: {=_xlfn.XLOOKUP( 1, (tblStoreMonthly[month_year]=TEXT($B$2,"yyyy-mm"))* (tblStoreMonthly[store_name]=A9), tblStoreMonthly[target_achievement_pct], "" )} -> 96.52 | H9: {=_xlfn.XLOOKUP( 1, (tblStoreMonthly[month_year]=TEXT($B$2,"yyyy-mm"))* (tblStoreMonthly[store_name]=A9), tblStoreMonthly[sales_vs_target], "" )} -> -574.52 | I9: =_xlfn.RANK.EQ(G9,$G$5:$G$29,0) -> 23 | J9: =IF( AND(E9<-5,G9<95), "Investigate", "")
A10: FreshMart London 06 | B10: =_xlfn.XLOOKUP(A10,tblStoreMonthly[store_name],tblStoreMonthly[store_format]) -> Supermarket | C10: =_xlfn.XLOOKUP(A10,tblStoreMonthly[store_name],tblStoreMonthly[region]) -> London | D10: {=_xlfn.XLOOKUP(1,(tblStoreMonthly[month_year]=TEXT($B$2,"yyyy-mm"))*(tblStoreMonthly[store_name]=A10),tblStoreMonthly[net_sales])} -> 15671.63 | E10: {=_xlfn.XLOOKUP(1,(tblStoreMonthly[month_year]=TEXT($B$2,"yyyy-mm"))*(tblStoreMonthly[store_name]=A10),tblStoreMonthly[mom_sales_growth_pct])} -> 5.01 | F10: {=_xlfn.XLOOKUP(1,(tblStoreMonthly[month_year]=TEXT($B$2,"yyyy-mm"))*(tblStoreMonthly[store_name]=A10),tblStoreMonthly[sales_target])} -> 14780.06 | G10: {=_xlfn.XLOOKUP( 1, (tblStoreMonthly[month_year]=TEXT($B$2,"yyyy-mm"))* (tblStoreMonthly[store_name]=A10), tblStoreMonthly[target_achievement_pct], "" )} -> 106.03 | H10: {=_xlfn.XLOOKUP( 1, (tblStoreMonthly[month_year]=TEXT($B$2,"yyyy-mm"))* (tblStoreMonthly[store_name]=A10), tblStoreMonthly[sales_vs_target], "" )} -> 891.57 | I10: =_xlfn.RANK.EQ(G10,$G$5:$G$29,0) -> 1 | J10: =IF( AND(E10<-5,G10<95), "Investigate", "")
A11: FreshMart South East 07 | B11: =_xlfn.XLOOKUP(A11,tblStoreMonthly[store_name],tblStoreMonthly[store_format]) -> Supermarket | C11: =_xlfn.XLOOKUP(A11,tblStoreMonthly[store_name],tblStoreMonthly[region]) -> South East | D11: {=_xlfn.XLOOKUP(1,(tblStoreMonthly[month_year]=TEXT($B$2,"yyyy-mm"))*(tblStoreMonthly[store_name]=A11),tblStoreMonthly[net_sales])} -> 16509.62 | E11: {=_xlfn.XLOOKUP(1,(tblStoreMonthly[month_year]=TEXT($B$2,"yyyy-mm"))*(tblStoreMonthly[store_name]=A11),tblStoreMonthly[mom_sales_growth_pct])} -> 1.21 | F11: {=_xlfn.XLOOKUP(1,(tblStoreMonthly[month_year]=TEXT($B$2,"yyyy-mm"))*(tblStoreMonthly[store_name]=A11),tblStoreMonthly[sales_target])} -> 15954.2 | G11: {=_xlfn.XLOOKUP( 1, (tblStoreMonthly[month_year]=TEXT($B$2,"yyyy-mm"))* (tblStoreMonthly[store_name]=A11), tblStoreMonthly[target_achievement_pct], "" )} -> 103.48 | H11: {=_xlfn.XLOOKUP( 1, (tblStoreMonthly[month_year]=TEXT($B$2,"yyyy-mm"))* (tblStoreMonthly[store_name]=A11), tblStoreMonthly[sales_vs_target], "" )} -> 555.42 | I11: =_xlfn.RANK.EQ(G11,$G$5:$G$29,0) -> 4 | J11: =IF( AND(E11<-5,G11<95), "Investigate", "")
A12: FreshMart South West 08 | B12: =_xlfn.XLOOKUP(A12,tblStoreMonthly[store_name],tblStoreMonthly[store_format]) -> Supermarket | C12: =_xlfn.XLOOKUP(A12,tblStoreMonthly[store_name],tblStoreMonthly[region]) -> South West | D12: {=_xlfn.XLOOKUP(1,(tblStoreMonthly[month_year]=TEXT($B$2,"yyyy-mm"))*(tblStoreMonthly[store_name]=A12),tblStoreMonthly[net_sales])} -> 17344.16 | E12: {=_xlfn.XLOOKUP(1,(tblStoreMonthly[month_year]=TEXT($B$2,"yyyy-mm"))*(tblStoreMonthly[store_name]=A12),tblStoreMonthly[mom_sales_growth_pct])} -> 6.72 | F12: {=_xlfn.XLOOKUP(1,(tblStoreMonthly[month_year]=TEXT($B$2,"yyyy-mm"))*(tblStoreMonthly[store_name]=A12),tblStoreMonthly[sales_target])} -> 16826.49 | G12: {=_xlfn.XLOOKUP( 1, (tblStoreMonthly[month_year]=TEXT($B$2,"yyyy-mm"))* (tblStoreMonthly[store_name]=A12), tblStoreMonthly[target_achievement_pct], "" )} -> 103.08 | H12: {=_xlfn.XLOOKUP( 1, (tblStoreMonthly[month_year]=TEXT($B$2,"yyyy-mm"))* (tblStoreMonthly[store_name]=A12), tblStoreMonthly[sales_vs_target], "" )} -> 517.67 | I12: =_xlfn.RANK.EQ(G12,$G$5:$G$29,0) -> 9 | J12: =IF( AND(E12<-5,G12<95), "Investigate", "")
A13: FreshMart Midlands 09 | B13: =_xlfn.XLOOKUP(A13,tblStoreMonthly[store_name],tblStoreMonthly[store_format]) -> Supermarket | C13: =_xlfn.XLOOKUP(A13,tblStoreMonthly[store_name],tblStoreMonthly[region]) -> Midlands | D13: {=_xlfn.XLOOKUP(1,(tblStoreMonthly[month_year]=TEXT($B$2,"yyyy-mm"))*(tblStoreMonthly[store_name]=A13),tblStoreMonthly[net_sales])} -> 15542.38 | E13: {=_xlfn.XLOOKUP(1,(tblStoreMonthly[month_year]=TEXT($B$2,"yyyy-mm"))*(tblStoreMonthly[store_name]=A13),tblStoreMonthly[mom_sales_growth_pct])} -> 1.93 | F13: {=_xlfn.XLOOKUP(1,(tblStoreMonthly[month_year]=TEXT($B$2,"yyyy-mm"))*(tblStoreMonthly[store_name]=A13),tblStoreMonthly[sales_target])} -> 15025.77 | G13: {=_xlfn.XLOOKUP( 1, (tblStoreMonthly[month_year]=TEXT($B$2,"yyyy-mm"))* (tblStoreMonthly[store_name]=A13), tblStoreMonthly[target_achievement_pct], "" )} -> 103.44 | H13: {=_xlfn.XLOOKUP( 1, (tblStoreMonthly[month_year]=TEXT($B$2,"yyyy-mm"))* (tblStoreMonthly[store_name]=A13), tblStoreMonthly[sales_vs_target], "" )} -> 516.61 | I13: =_xlfn.RANK.EQ(G13,$G$5:$G$29,0) -> 7 | J13: =IF( AND(E13<-5,G13<95), "Investigate", "")
A14: FreshMart North West 10 | B14: =_xlfn.XLOOKUP(A14,tblStoreMonthly[store_name],tblStoreMonthly[store_format]) -> Supermarket | C14: =_xlfn.XLOOKUP(A14,tblStoreMonthly[store_name],tblStoreMonthly[region]) -> North West | D14: {=_xlfn.XLOOKUP(1,(tblStoreMonthly[month_year]=TEXT($B$2,"yyyy-mm"))*(tblStoreMonthly[store_name]=A14),tblStoreMonthly[net_sales])} -> 17475.84 | E14: {=_xlfn.XLOOKUP(1,(tblStoreMonthly[month_year]=TEXT($B$2,"yyyy-mm"))*(tblStoreMonthly[store_name]=A14),tblStoreMonthly[mom_sales_growth_pct])} -> -0.17 | F14: {=_xlfn.XLOOKUP(1,(tblStoreMonthly[month_year]=TEXT($B$2,"yyyy-mm"))*(tblStoreMonthly[store_name]=A14),tblStoreMonthly[sales_target])} -> 17864.96 | G14: {=_xlfn.XLOOKUP( 1, (tblStoreMonthly[month_year]=TEXT($B$2,"yyyy-mm"))* (tblStoreMonthly[store_name]=A14), tblStoreMonthly[target_achievement_pct], "" )} -> 97.82 | H14: {=_xlfn.XLOOKUP( 1, (tblStoreMonthly[month_year]=TEXT($B$2,"yyyy-mm"))* (tblStoreMonthly[store_name]=A14), tblStoreMonthly[sales_vs_target], "" )} -> -389.12 | I14: =_xlfn.RANK.EQ(G14,$G$5:$G$29,0) -> 21 | J14: =IF( AND(E14<-5,G14<95), "Investigate", "")
A15: FreshMart London 11 | B15: =_xlfn.XLOOKUP(A15,tblStoreMonthly[store_name],tblStoreMonthly[store_format]) -> Supermarket | C15: =_xlfn.XLOOKUP(A15,tblStoreMonthly[store_name],tblStoreMonthly[region]) -> London | D15: {=_xlfn.XLOOKUP(1,(tblStoreMonthly[month_year]=TEXT($B$2,"yyyy-mm"))*(tblStoreMonthly[store_name]=A15),tblStoreMonthly[net_sales])} -> 17409.31 | E15: {=_xlfn.XLOOKUP(1,(tblStoreMonthly[month_year]=TEXT($B$2,"yyyy-mm"))*(tblStoreMonthly[store_name]=A15),tblStoreMonthly[mom_sales_growth_pct])} -> 14.65 | F15: {=_xlfn.XLOOKUP(1,(tblStoreMonthly[month_year]=TEXT($B$2,"yyyy-mm"))*(tblStoreMonthly[store_name]=A15),tblStoreMonthly[sales_target])} -> 17484.54 | G15: {=_xlfn.XLOOKUP( 1, (tblStoreMonthly[month_year]=TEXT($B$2,"yyyy-mm"))* (tblStoreMonthly[store_name]=A15), tblStoreMonthly[target_achievement_pct], "" )} -> 99.57 | H15: {=_xlfn.XLOOKUP( 1, (tblStoreMonthly[month_year]=TEXT($B$2,"yyyy-mm"))* (tblStoreMonthly[store_name]=A15), tblStoreMonthly[sales_vs_target], "" )} -> -75.23 | I15: =_xlfn.RANK.EQ(G15,$G$5:$G$29,0) -> 17 | J15: =IF( AND(E15<-5,G15<95), "Investigate", "")
A16: FreshMart South East 12 | B16: =_xlfn.XLOOKUP(A16,tblStoreMonthly[store_name],tblStoreMonthly[store_format]) -> Supermarket | C16: =_xlfn.XLOOKUP(A16,tblStoreMonthly[store_name],tblStoreMonthly[region]) -> South East | D16: {=_xlfn.XLOOKUP(1,(tblStoreMonthly[month_year]=TEXT($B$2,"yyyy-mm"))*(tblStoreMonthly[store_name]=A16),tblStoreMonthly[net_sales])} -> 16480.81 | E16: {=_xlfn.XLOOKUP(1,(tblStoreMonthly[month_year]=TEXT($B$2,"yyyy-mm"))*(tblStoreMonthly[store_name]=A16),tblStoreMonthly[mom_sales_growth_pct])} -> 1.06 | F16: {=_xlfn.XLOOKUP(1,(tblStoreMonthly[month_year]=TEXT($B$2,"yyyy-mm"))*(tblStoreMonthly[store_name]=A16),tblStoreMonthly[sales_target])} -> 16110.08 | G16: {=_xlfn.XLOOKUP( 1, (tblStoreMonthly[month_year]=TEXT($B$2,"yyyy-mm"))* (tblStoreMonthly[store_name]=A16), tblStoreMonthly[target_achievement_pct], "" )} -> 102.3 | H16: {=_xlfn.XLOOKUP( 1, (tblStoreMonthly[month_year]=TEXT($B$2,"yyyy-mm"))* (tblStoreMonthly[store_name]=A16), tblStoreMonthly[sales_vs_target], "" )} -> 370.73 | I16: =_xlfn.RANK.EQ(G16,$G$5:$G$29,0) -> 14 | J16: =IF( AND(E16<-5,G16<95), "Investigate", "")
A17: FreshMart South West 13 | B17: =_xlfn.XLOOKUP(A17,tblStoreMonthly[store_name],tblStoreMonthly[store_format]) -> Supermarket | C17: =_xlfn.XLOOKUP(A17,tblStoreMonthly[store_name],tblStoreMonthly[region]) -> South West | D17: {=_xlfn.XLOOKUP(1,(tblStoreMonthly[month_year]=TEXT($B$2,"yyyy-mm"))*(tblStoreMonthly[store_name]=A17),tblStoreMonthly[net_sales])} -> 17090.96 | E17: {=_xlfn.XLOOKUP(1,(tblStoreMonthly[month_year]=TEXT($B$2,"yyyy-mm"))*(tblStoreMonthly[store_name]=A17),tblStoreMonthly[mom_sales_growth_pct])} -> 8.29 | F17: {=_xlfn.XLOOKUP(1,(tblStoreMonthly[month_year]=TEXT($B$2,"yyyy-mm"))*(tblStoreMonthly[store_name]=A17),tblStoreMonthly[sales_target])} -> 16587.7 | G17: {=_xlfn.XLOOKUP( 1, (tblStoreMonthly[month_year]=TEXT($B$2,"yyyy-mm"))* (tblStoreMonthly[store_name]=A17), tblStoreMonthly[target_achievement_pct], "" )} -> 103.03 | H17: {=_xlfn.XLOOKUP( 1, (tblStoreMonthly[month_year]=TEXT($B$2,"yyyy-mm"))* (tblStoreMonthly[store_name]=A17), tblStoreMonthly[sales_vs_target], "" )} -> 503.26 | I17: =_xlfn.RANK.EQ(G17,$G$5:$G$29,0) -> 11 | J17: =IF( AND(E17<-5,G17<95), "Investigate", "")
... A29: FreshMart North West 25 | B29: =_xlfn.XLOOKUP(A29,tblStoreMonthly[store_name],tblStoreMonthly[store_format]) -> Convenience | C29: =_xlfn.XLOOKUP(A29,tblStoreMonthly[store_name],tblStoreMonthly[region]) -> North West | D29: {=_xlfn.XLOOKUP(1,(tblStoreMonthly[month_year]=TEXT($B$2,"yyyy-mm"))*(tblStoreMonthly[store_name]=A29),tblStoreMonthly[net_sales])} -> 19165.48 | E29: {=_xlfn.XLOOKUP(1,(tblStoreMonthly[month_year]=TEXT($B$2,"yyyy-mm"))*(tblStoreMonthly[store_name]=A29),tblStoreMonthly[mom_sales_growth_pct])} -> 5.03 | F29: {=_xlfn.XLOOKUP(1,(tblStoreMonthly[month_year]=TEXT($B$2,"yyyy-mm"))*(tblStoreMonthly[store_name]=A29),tblStoreMonthly[sales_target])} -> 18520.71 | G29: {=_xlfn.XLOOKUP( 1, (tblStoreMonthly[month_year]=TEXT($B$2,"yyyy-mm"))* (tblStoreMonthly[store_name]=A29), tblStoreMonthly[target_achievement_pct], "" )} -> 103.48 | H29: {=_xlfn.XLOOKUP( 1, (tblStoreMonthly[month_year]=TEXT($B$2,"yyyy-mm"))* (tblStoreMonthly[store_name]=A29), tblStoreMonthly[sales_vs_target], "" )} -> 644.77 | I29: =_xlfn.RANK.EQ(G29,$G$5:$G$29,0) -> 4 | J29: =IF( AND(E29<-5,G29<95), "Investigate", "")
A31: Top Target Achievers | D31: Stores Requiring Attention
A32: Stores | B32: Target Achievement | D32: Store | E32: MoM % | F32: Target %
A33: {=_xlfn.TAKE( _xlfn._xlws.SORT( _xlfn._xlws.FILTER( _xlfn.HSTACK($A$5:$A$24,$G$5:$G$24), $A$5:$A$24<>"" ), 2,-1 ), 3 )} -> FreshMart London 06 | B33: 106.03 | D33: {=IFERROR( _xlfn.TAKE( _xlfn._xlws.SORT( _xlfn._xlws.FILTER( _xlfn.HSTACK($A$5:$A$24,$E$5:$E$24,$G$5:$G$24), $J$5:$J$24="Investigate" ), 3,1 ), 3 ), "No stores flagged" )} -> No stores flagged
A34: FreshMart North West 15 | B34: 106.03
A35: FreshMart South East 07 | B35: 103.48

Sheet Trading Performance
A1: FreshMart Monthly Trading Performance
A2: 2025 Trading Year
A4: KPI | B4: 45658 | C4: 45689 | D4: 45717 | E4: 45748 | F4: 45778 | G4: 45809 | H4: 45839 | I4: 45870 | J4: 45901 | K4: 45931 | L4: 45962 | M4: 45992
A5: Net Sales | B5: {=_xlfn.XLOOKUP(TEXT(B$4,"yyyy-mm"),tblCompanyMonthly[[month_year]:[month_year]],tblCompanyMonthly[[net_sales]:[net_sales]],"")} -> 347199.18 | C5: {=_xlfn.XLOOKUP(TEXT(C$4,"yyyy-mm"),tblCompanyMonthly[[month_year]:[month_year]],tblCompanyMonthly[[net_sales]:[net_sales]],"")} -> 317297.71 | D5: {=_xlfn.XLOOKUP(TEXT(D$4,"yyyy-mm"),tblCompanyMonthly[[month_year]:[month_year]],tblCompanyMonthly[[net_sales]:[net_sales]],"")} -> 391277.02 | E5: {=_xlfn.XLOOKUP(TEXT(E$4,"yyyy-mm"),tblCompanyMonthly[[month_year]:[month_year]],tblCompanyMonthly[[net_sales]:[net_sales]],"")} -> 373482.58 | F5: {=_xlfn.XLOOKUP(TEXT(F$4,"yyyy-mm"),tblCompanyMonthly[[month_year]:[month_year]],tblCompanyMonthly[[net_sales]:[net_sales]],"")} -> 387910.67 | G5: {=_xlfn.XLOOKUP(TEXT(G$4,"yyyy-mm"),tblCompanyMonthly[[month_year]:[month_year]],tblCompanyMonthly[[net_sales]:[net_sales]],"")} -> 376894.58 | H5: {=_xlfn.XLOOKUP(TEXT(H$4,"yyyy-mm"),tblCompanyMonthly[[month_year]:[month_year]],tblCompanyMonthly[[net_sales]:[net_sales]],"")} -> 426209.48 | I5: {=_xlfn.XLOOKUP(TEXT(I$4,"yyyy-mm"),tblCompanyMonthly[[month_year]:[month_year]],tblCompanyMonthly[[net_sales]:[net_sales]],"")} -> 441528.02 | ... M5: {=_xlfn.XLOOKUP(TEXT(M$4,"yyyy-mm"),tblCompanyMonthly[[month_year]:[month_year]],tblCompanyMonthly[[net_sales]:[net_sales]],"")} -> 433925.11
A6: MoM Sales % | B6: {=_xlfn.XLOOKUP(TEXT(B$4,"yyyy-mm"),tblCompanyMonthly[[month_year]:[month_year]],tblCompanyMonthly[[sales_mom_pct]:[sales_mom_pct]],"")} -> 0 | C6: {=_xlfn.XLOOKUP(TEXT(C$4,"yyyy-mm"),tblCompanyMonthly[[month_year]:[month_year]],tblCompanyMonthly[[sales_mom_pct]:[sales_mom_pct]],"")} -> -8.61 | D6: {=_xlfn.XLOOKUP(TEXT(D$4,"yyyy-mm"),tblCompanyMonthly[[month_year]:[month_year]],tblCompanyMonthly[[sales_mom_pct]:[sales_mom_pct]],"")} -> 23.32 | E6: {=_xlfn.XLOOKUP(TEXT(E$4,"yyyy-mm"),tblCompanyMonthly[[month_year]:[month_year]],tblCompanyMonthly[[sales_mom_pct]:[sales_mom_pct]],"")} -> -4.55 | F6: {=_xlfn.XLOOKUP(TEXT(F$4,"yyyy-mm"),tblCompanyMonthly[[month_year]:[month_year]],tblCompanyMonthly[[sales_mom_pct]:[sales_mom_pct]],"")} -> 3.86 | G6: {=_xlfn.XLOOKUP(TEXT(G$4,"yyyy-mm"),tblCompanyMonthly[[month_year]:[month_year]],tblCompanyMonthly[[sales_mom_pct]:[sales_mom_pct]],"")} -> -2.84 | H6: {=_xlfn.XLOOKUP(TEXT(H$4,"yyyy-mm"),tblCompanyMonthly[[month_year]:[month_year]],tblCompanyMonthly[[sales_mom_pct]:[sales_mom_pct]],"")} -> 13.08 | I6: {=_xlfn.XLOOKUP(TEXT(I$4,"yyyy-mm"),tblCompanyMonthly[[month_year]:[month_year]],tblCompanyMonthly[[sales_mom_pct]:[sales_mom_pct]],"")} -> 3.59 | ... M6: {=_xlfn.XLOOKUP(TEXT(M$4,"yyyy-mm"),tblCompanyMonthly[[month_year]:[month_year]],tblCompanyMonthly[[sales_mom_pct]:[sales_mom_pct]],"")} -> 4.11
A7: Sales Target | B7: {=_xlfn.XLOOKUP(TEXT(B$4,"yyyy-mm"),tblCompanyMonthly[[month_year]:[month_year]],tblCompanyMonthly[[sales_target]:[sales_target]],"")} -> 348047.53 | C7: {=_xlfn.XLOOKUP(TEXT(C$4,"yyyy-mm"),tblCompanyMonthly[[month_year]:[month_year]],tblCompanyMonthly[[sales_target]:[sales_target]],"")} -> 315138.36 | D7: {=_xlfn.XLOOKUP(TEXT(D$4,"yyyy-mm"),tblCompanyMonthly[[month_year]:[month_year]],tblCompanyMonthly[[sales_target]:[sales_target]],"")} -> 386010.06 | E7: {=_xlfn.XLOOKUP(TEXT(E$4,"yyyy-mm"),tblCompanyMonthly[[month_year]:[month_year]],tblCompanyMonthly[[sales_target]:[sales_target]],"")} -> 367268.6 | F7: {=_xlfn.XLOOKUP(TEXT(F$4,"yyyy-mm"),tblCompanyMonthly[[month_year]:[month_year]],tblCompanyMonthly[[sales_target]:[sales_target]],"")} -> 382254.6 | G7: {=_xlfn.XLOOKUP(TEXT(G$4,"yyyy-mm"),tblCompanyMonthly[[month_year]:[month_year]],tblCompanyMonthly[[sales_target]:[sales_target]],"")} -> 373757.12 | H7: {=_xlfn.XLOOKUP(TEXT(H$4,"yyyy-mm"),tblCompanyMonthly[[month_year]:[month_year]],tblCompanyMonthly[[sales_target]:[sales_target]],"")} -> 424003.06 | I7: {=_xlfn.XLOOKUP(TEXT(I$4,"yyyy-mm"),tblCompanyMonthly[[month_year]:[month_year]],tblCompanyMonthly[[sales_target]:[sales_target]],"")} -> 440642.39 | ... M7: {=_xlfn.XLOOKUP(TEXT(M$4,"yyyy-mm"),tblCompanyMonthly[[month_year]:[month_year]],tblCompanyMonthly[[sales_target]:[sales_target]],"")} -> 426923.77
A8: Target Achievement % | B8: {=_xlfn.XLOOKUP(TEXT(B$4,"yyyy-mm"),tblCompanyMonthly[[month_year]:[month_year]],tblCompanyMonthly[[target_achievement_pct]:[target_achievement_pct]],"")} -> 99.76 | C8: {=_xlfn.XLOOKUP(TEXT(C$4,"yyyy-mm"),tblCompanyMonthly[[month_year]:[month_year]],tblCompanyMonthly[[target_achievement_pct]:[target_achievement_pct]],"")} -> 100.69 | D8: {=_xlfn.XLOOKUP(TEXT(D$4,"yyyy-mm"),tblCompanyMonthly[[month_year]:[month_year]],tblCompanyMonthly[[target_achievement_pct]:[target_achievement_pct]],"")} -> 101.36 | E8: {=_xlfn.XLOOKUP(TEXT(E$4,"yyyy-mm"),tblCompanyMonthly[[month_year]:[month_year]],tblCompanyMonthly[[target_achievement_pct]:[target_achievement_pct]],"")} -> 101.69 | F8: {=_xlfn.XLOOKUP(TEXT(F$4,"yyyy-mm"),tblCompanyMonthly[[month_year]:[month_year]],tblCompanyMonthly[[target_achievement_pct]:[target_achievement_pct]],"")} -> 101.48 | G8: {=_xlfn.XLOOKUP(TEXT(G$4,"yyyy-mm"),tblCompanyMonthly[[month_year]:[month_year]],tblCompanyMonthly[[target_achievement_pct]:[target_achievement_pct]],"")} -> 100.84 | H8: {=_xlfn.XLOOKUP(TEXT(H$4,"yyyy-mm"),tblCompanyMonthly[[month_year]:[month_year]],tblCompanyMonthly[[target_achievement_pct]:[target_achievement_pct]],"")} -> 100.52 | I8: {=_xlfn.XLOOKUP(TEXT(I$4,"yyyy-mm"),tblCompanyMonthly[[month_year]:[month_year]],tblCompanyMonthly[[target_achievement_pct]:[target_achievement_pct]],"")} -> 100.2 | ... M8: {=_xlfn.XLOOKUP(TEXT(M$4,"yyyy-mm"),tblCompanyMonthly[[month_year]:[month_year]],tblCompanyMonthly[[target_achievement_pct]:[target_achievement_pct]],"")} -> 101.64
A9: Transactions | B9: {=_xlfn.XLOOKUP(TEXT(B$4,"yyyy-mm"),tblCompanyMonthly[[month_year]:[month_year]],tblCompanyMonthly[[transactions]:[transactions]],"")} -> 8565 | C9: {=_xlfn.XLOOKUP(TEXT(C$4,"yyyy-mm"),tblCompanyMonthly[[month_year]:[month_year]],tblCompanyMonthly[[transactions]:[transactions]],"")} -> 7825 | D9: {=_xlfn.XLOOKUP(TEXT(D$4,"yyyy-mm"),tblCompanyMonthly[[month_year]:[month_year]],tblCompanyMonthly[[transactions]:[transactions]],"")} -> 9497 | E9: {=_xlfn.XLOOKUP(TEXT(E$4,"yyyy-mm"),tblCompanyMonthly[[month_year]:[month_year]],tblCompanyMonthly[[transactions]:[transactions]],"")} -> 9230 | F9: {=_xlfn.XLOOKUP(TEXT(F$4,"yyyy-mm"),tblCompanyMonthly[[month_year]:[month_year]],tblCompanyMonthly[[transactions]:[transactions]],"")} -> 9571 | G9: {=_xlfn.XLOOKUP(TEXT(G$4,"yyyy-mm"),tblCompanyMonthly[[month_year]:[month_year]],tblCompanyMonthly[[transactions]:[transactions]],"")} -> 9251 | H9: {=_xlfn.XLOOKUP(TEXT(H$4,"yyyy-mm"),tblCompanyMonthly[[month_year]:[month_year]],tblCompanyMonthly[[transactions]:[transactions]],"")} -> 10268 | I9: {=_xlfn.XLOOKUP(TEXT(I$4,"yyyy-mm"),tblCompanyMonthly[[month_year]:[month_year]],tblCompanyMonthly[[transactions]:[transactions]],"")} -> 10728 | ... M9: {=_xlfn.XLOOKUP(TEXT(M$4,"yyyy-mm"),tblCompanyMonthly[[month_year]:[month_year]],tblCompanyMonthly[[transactions]:[transactions]],"")} -> 10404
A10: MoM Transactions % | B10: {=_xlfn.XLOOKUP(TEXT(B$4,"yyyy-mm"),tblCompanyMonthly[[month_year]:[month_year]],tblCompanyMonthly[[transactions_mom_pct]:[transactions_mom_pct]],"")} -> 0 | C10: {=_xlfn.XLOOKUP(TEXT(C$4,"yyyy-mm"),tblCompanyMonthly[[month_year]:[month_year]],tblCompanyMonthly[[transactions_mom_pct]:[transactions_mom_pct]],"")} -> -8.64 | D10: {=_xlfn.XLOOKUP(TEXT(D$4,"yyyy-mm"),tblCompanyMonthly[[month_year]:[month_year]],tblCompanyMonthly[[transactions_mom_pct]:[transactions_mom_pct]],"")} -> 21.37 | E10: {=_xlfn.XLOOKUP(TEXT(E$4,"yyyy-mm"),tblCompanyMonthly[[month_year]:[month_year]],tblCompanyMonthly[[transactions_mom_pct]:[transactions_mom_pct]],"")} -> -2.81 | F10: {=_xlfn.XLOOKUP(TEXT(F$4,"yyyy-mm"),tblCompanyMonthly[[month_year]:[month_year]],tblCompanyMonthly[[transactions_mom_pct]:[transactions_mom_pct]],"")} -> 3.69 | G10: {=_xlfn.XLOOKUP(TEXT(G$4,"yyyy-mm"),tblCompanyMonthly[[month_year]:[month_year]],tblCompanyMonthly[[transactions_mom_pct]:[transactions_mom_pct]],"")} -> -3.34 | H10: {=_xlfn.XLOOKUP(TEXT(H$4,"yyyy-mm"),tblCompanyMonthly[[month_year]:[month_year]],tblCompanyMonthly[[transactions_mom_pct]:[transactions_mom_pct]],"")} -> 10.99 | I10: {=_xlfn.XLOOKUP(TEXT(I$4,"yyyy-mm"),tblCompanyMonthly[[month_year]:[month_year]],tblCompanyMonthly[[transactions_mom_pct]:[transactions_mom_pct]],"")} -> 4.48 | ... M10: {=_xlfn.XLOOKUP(TEXT(M$4,"yyyy-mm"),tblCompanyMonthly[[month_year]:[month_year]],tblCompanyMonthly[[transactions_mom_pct]:[transactions_mom_pct]],"")} -> 2.91
A11: ATV | B11: {=_xlfn.XLOOKUP(TEXT(B$4,"yyyy-mm"),tblCompanyMonthly[[month_year]:[month_year]],tblCompanyMonthly[[avg_transaction_value]:[avg_transaction_value]],"")} -> 40.54 | C11: {=_xlfn.XLOOKUP(TEXT(C$4,"yyyy-mm"),tblCompanyMonthly[[month_year]:[month_year]],tblCompanyMonthly[[avg_transaction_value]:[avg_transaction_value]],"")} -> 40.55 | D11: {=_xlfn.XLOOKUP(TEXT(D$4,"yyyy-mm"),tblCompanyMonthly[[month_year]:[month_year]],tblCompanyMonthly[[avg_transaction_value]:[avg_transaction_value]],"")} -> 41.2 | E11: {=_xlfn.XLOOKUP(TEXT(E$4,"yyyy-mm"),tblCompanyMonthly[[month_year]:[month_year]],tblCompanyMonthly[[avg_transaction_value]:[avg_transaction_value]],"")} -> 40.46 | F11: {=_xlfn.XLOOKUP(TEXT(F$4,"yyyy-mm"),tblCompanyMonthly[[month_year]:[month_year]],tblCompanyMonthly[[avg_transaction_value]:[avg_transaction_value]],"")} -> 40.53 | G11: {=_xlfn.XLOOKUP(TEXT(G$4,"yyyy-mm"),tblCompanyMonthly[[month_year]:[month_year]],tblCompanyMonthly[[avg_transaction_value]:[avg_transaction_value]],"")} -> 40.74 | H11: {=_xlfn.XLOOKUP(TEXT(H$4,"yyyy-mm"),tblCompanyMonthly[[month_year]:[month_year]],tblCompanyMonthly[[avg_transaction_value]:[avg_transaction_value]],"")} -> 41.51 | I11: {=_xlfn.XLOOKUP(TEXT(I$4,"yyyy-mm"),tblCompanyMonthly[[month_year]:[month_year]],tblCompanyMonthly[[avg_transaction_value]:[avg_transaction_value]],"")} -> 41.16 | ... M11: {=_xlfn.XLOOKUP(TEXT(M$4,"yyyy-mm"),tblCompanyMonthly[[month_year]:[month_year]],tblCompanyMonthly[[avg_transaction_value]:[avg_transaction_value]],"")} -> 41.71
A12: UPT | B12: {=_xlfn.XLOOKUP(TEXT(B$4,"yyyy-mm"),tblCompanyMonthly[[month_year]:[month_year]],tblCompanyMonthly[[units_per_transaction]:[units_per_transaction]],"")} -> 5.13 | C12: {=_xlfn.XLOOKUP(TEXT(C$4,"yyyy-mm"),tblCompanyMonthly[[month_year]:[month_year]],tblCompanyMonthly[[units_per_transaction]:[units_per_transaction]],"")} -> 5.15 | D12: {=_xlfn.XLOOKUP(TEXT(D$4,"yyyy-mm"),tblCompanyMonthly[[month_year]:[month_year]],tblCompanyMonthly[[units_per_transaction]:[units_per_transaction]],"")} -> 5.16 | E12: {=_xlfn.XLOOKUP(TEXT(E$4,"yyyy-mm"),tblCompanyMonthly[[month_year]:[month_year]],tblCompanyMonthly[[units_per_transaction]:[units_per_transaction]],"")} -> 5.1 | F12: {=_xlfn.XLOOKUP(TEXT(F$4,"yyyy-mm"),tblCompanyMonthly[[month_year]:[month_year]],tblCompanyMonthly[[units_per_transaction]:[units_per_transaction]],"")} -> 5.14 | G12: {=_xlfn.XLOOKUP(TEXT(G$4,"yyyy-mm"),tblCompanyMonthly[[month_year]:[month_year]],tblCompanyMonthly[[units_per_transaction]:[units_per_transaction]],"")} -> 5.15 | H12: {=_xlfn.XLOOKUP(TEXT(H$4,"yyyy-mm"),tblCompanyMonthly[[month_year]:[month_year]],tblCompanyMonthly[[units_per_transaction]:[units_per_transaction]],"")} -> 5.16 | I12: {=_xlfn.XLOOKUP(TEXT(I$4,"yyyy-mm"),tblCompanyMonthly[[month_year]:[month_year]],tblCompanyMonthly[[units_per_transaction]:[units_per_transaction]],"")} -> 5.14 | ... M12: {=_xlfn.XLOOKUP(TEXT(M$4,"yyyy-mm"),tblCompanyMonthly[[month_year]:[month_year]],tblCompanyMonthly[[units_per_transaction]:[units_per_transaction]],"")} -> 5.17
A13: ASP | B13: {=_xlfn.XLOOKUP(TEXT(B$4,"yyyy-mm"),tblCompanyMonthly[[month_year]:[month_year]],tblCompanyMonthly[[avg_selling_price]:[avg_selling_price]],"")} -> 7.91 | C13: {=_xlfn.XLOOKUP(TEXT(C$4,"yyyy-mm"),tblCompanyMonthly[[month_year]:[month_year]],tblCompanyMonthly[[avg_selling_price]:[avg_selling_price]],"")} -> 7.88 | D13: {=_xlfn.XLOOKUP(TEXT(D$4,"yyyy-mm"),tblCompanyMonthly[[month_year]:[month_year]],tblCompanyMonthly[[avg_selling_price]:[avg_selling_price]],"")} -> 7.99 | E13: {=_xlfn.XLOOKUP(TEXT(E$4,"yyyy-mm"),tblCompanyMonthly[[month_year]:[month_year]],tblCompanyMonthly[[avg_selling_price]:[avg_selling_price]],"")} -> 7.94 | F13: {=_xlfn.XLOOKUP(TEXT(F$4,"yyyy-mm"),tblCompanyMonthly[[month_year]:[month_year]],tblCompanyMonthly[[avg_selling_price]:[avg_selling_price]],"")} -> 7.89 | G13: {=_xlfn.XLOOKUP(TEXT(G$4,"yyyy-mm"),tblCompanyMonthly[[month_year]:[month_year]],tblCompanyMonthly[[avg_selling_price]:[avg_selling_price]],"")} -> 7.91 | H13: {=_xlfn.XLOOKUP(TEXT(H$4,"yyyy-mm"),tblCompanyMonthly[[month_year]:[month_year]],tblCompanyMonthly[[avg_selling_price]:[avg_selling_price]],"")} -> 8.04 | I13: {=_xlfn.XLOOKUP(TEXT(I$4,"yyyy-mm"),tblCompanyMonthly[[month_year]:[month_year]],tblCompanyMonthly[[avg_selling_price]:[avg_selling_price]],"")} -> 8.01 | ... M13: {=_xlfn.XLOOKUP(TEXT(M$4,"yyyy-mm"),tblCompanyMonthly[[month_year]:[month_year]],tblCompanyMonthly[[avg_selling_price]:[avg_selling_price]],"")} -> 8.07

Sheet tblStoreMonthly
A1: month_year | B1: store_id | C1: store_name | D1: store_format | E1: region | F1: net_sales | G1: previous_month_sales | H1: mom_sales_variance | I1: mom_sales_growth_pct | J1: sales_target | K1: sales_vs_target | L1: target_achievement_pct
A2: 2025-01 | B2: ST001 | C2: FreshMart London 01 | D2: Supermarket | E2: London | F2: 16297.83 | J2: 17205.08 | K2: -907.25 | L2: 94.73
A3: 2025-02 | B3: ST001 | C3: FreshMart London 01 | D3: Supermarket | E3: London | F3: 14538.35 | G3: 16297.83 | H3: -1759.48 | I3: -10.8 | J3: 15136.94 | K3: -598.59 | L3: 96.05
A4: 2025-03 | B4: ST001 | C4: FreshMart London 01 | D4: Supermarket | E4: London | F4: 17484.49 | G4: 14538.35 | H4: 2946.14 | I4: 20.26 | J4: 17873.8 | K4: -389.31 | L4: 97.82
A5: 2025-04 | B5: ST001 | C5: FreshMart London 01 | D5: Supermarket | E5: London | F5: 15897.12 | G5: 17484.49 | H5: -1587.37 | I5: -9.08 | J5: 15965.81 | K5: -68.69 | L5: 99.57
A6: 2025-05 | B6: ST001 | C6: FreshMart London 01 | D6: Supermarket | E6: London | F6: 14183.32 | G6: 15897.12 | H6: -1713.8 | I6: -10.78 | J6: 13864.27 | K6: 319.05 | L6: 102.3
A7: 2025-06 | B7: ST001 | C7: FreshMart London 01 | D7: Supermarket | E7: London | F7: 15870.27 | G7: 14183.32 | H7: 1686.95 | I7: 11.89 | J7: 15402.95 | K7: 467.32 | L7: 103.03
A8: 2025-07 | B8: ST001 | C8: FreshMart London 01 | D8: Supermarket | E8: London | F8: 16859.52 | G8: 15870.27 | H8: 989.25 | I8: 6.23 | J8: 17467.46 | K8: -607.94 | L8: 96.52
A9: 2025-08 | B9: ST001 | C9: FreshMart London 01 | D9: Supermarket | E9: London | F9: 16910.19 | G9: 16859.52 | H9: 50.67 | I9: 0.3 | J9: 15948.16 | K9: 962.03 | L9: 106.03
A10: 2025-09 | B10: ST001 | C10: FreshMart London 01 | D10: Supermarket | E10: London | F10: 13585.1 | G10: 16910.19 | H10: -3325.09 | I10: -19.66 | J10: 13128.07 | K10: 457.03 | L10: 103.48
A11: 2025-10 | B11: ST001 | C11: FreshMart London 01 | D11: Supermarket | E11: London | F11: 16082.32 | G11: 13585.1 | H11: 2497.22 | I11: 18.38 | J11: 16977.58 | K11: -895.26 | L11: 94.73
A12: 2025-11 | B12: ST001 | C12: FreshMart London 01 | D12: Supermarket | E12: London | F12: 15105.34 | G12: 16082.32 | H12: -976.98 | I12: -6.07 | J12: 15727.28 | K12: -621.94 | L12: 96.05
A13: 2025-12 | B13: ST001 | C13: FreshMart London 01 | D13: Supermarket | E13: London | F13: 15619.51 | G13: 15105.34 | H13: 514.17 | I13: 3.4 | J13: 15967.3 | K13: -347.79 | L13: 97.82
A14: 2025-01 | B14: ST002 | C14: FreshMart South East 02 | D14: Supermarket | E14: South East | F14: 16171.93 | J14: 16837.78 | K14: -665.85 | L14: 96.05
A15: 2025-02 | B15: ST002 | C15: FreshMart South East 02 | D15: Supermarket | E15: South East | F15: 15443.34 | G15: 16171.93 | H15: -728.59 | I15: -4.51 | J15: 15787.2 | K15: -343.86 | L15: 97.82
A16: 2025-03 | B16: ST002 | C16: FreshMart South East 02 | D16: Supermarket | E16: South East | F16: 16657.12 | G16: 15443.34 | H16: 1213.78 | I16: 7.86 | J16: 16729.09 | K16: -71.97 | L16: 99.57
A17: 2025-04 | B17: ST002 | C17: FreshMart South East 02 | D17: Supermarket | E17: South East | F17: 16459.11 | G17: 16657.12 | H17: -198.01 | I17: -1.19 | J17: 16088.87 | K17: 370.24 | L17: 102.3
A18: 2025-05 | B18: ST002 | C18: FreshMart South East 02 | D18: Supermarket | E18: South East | F18: 16552.53 | G18: 16459.11 | H18: 93.42 | I18: 0.57 | J18: 16065.12 | K18: 487.41 | L18: 103.03
A19: 2025-06 | B19: ST002 | C19: FreshMart South East 02 | D19: Supermarket | E19: South East | F19: 15541.7 | G19: 16552.53 | H19: -1010.83 | I19: -6.11 | J19: 16102.12 | K19: -560.42 | L19: 96.52
A20: 2025-07 | B20: ST002 | C20: FreshMart South East 02 | D20: Supermarket | E20: South East | F20: 15657.13 | G20: 15541.7 | H20: 115.43 | I20: 0.74 | J20: 14766.38 | K20: 890.75 | L20: 106.03
A21: 2025-08 | B21: ST002 | C21: FreshMart South East 02 | D21: Supermarket | E21: South East | F21: 16928.17 | G21: 15657.13 | H21: 1271.04 | I21: 8.12 | J21: 16358.67 | K21: 569.5 | L21: 103.48
A22: 2025-09 | B22: ST002 | C22: FreshMart South East 02 | D22: Supermarket | E22: South East | F22: 16809.68 | G22: 16928.17 | H22: -118.49 | I22: -0.7 | J22: 16307.96 | K22: 501.72 | L22: 103.08
A23: 2025-10 | B23: ST002 | C23: FreshMart South East 02 | D23: Supermarket | E23: South East | F23: 16297.79 | G23: 16809.68 | H23: -511.89 | I23: -3.05 | J23: 16968.83 | K23: -671.04 | L23: 96.05
A24: 2025-11 | B24: ST002 | C24: FreshMart South East 02 | D24: Supermarket | E24: South East | F24: 15147.17 | G24: 16297.79 | H24: -1150.62 | I24: -7.06 | J24: 15484.44 | K24: -337.27 | L24: 97.82
A25: 2025-12 | B25: ST002 | C25: FreshMart South East 02 | D25: Supermarket | E25: South East | F25: 16483.11 | G25: 15147.17 | H25: 1335.94 | I25: 8.82 | J25: 16554.33 | K25: -71.22 | L25: 99.57
A26: 2025-01 | B26: ST003 | C26: FreshMart South West 03 | D26: Supermarket | E26: South West | F26: 16338.8 | J26: 16702.6 | K26: -363.8 | L26: 97.82
A27: 2025-02 | B27: ST003 | C27: FreshMart South West 03 | D27: Supermarket | E27: South West | F27: 14270.44 | G27: 16338.8 | H27: -2068.36 | I27: -12.66 | J27: 14332.1 | K27: -61.66 | L27: 99.57
A28: 2025-03 | B28: ST003 | C28: FreshMart South West 03 | D28: Supermarket | E28: South West | F28: 15320.75 | G28: 14270.44 | H28: 1050.31 | I28: 7.36 | J28: 14976.11 | K28: 344.64 | L28: 102.3
A29: 2025-04 | B29: ST003 | C29: FreshMart South West 03 | D29: Supermarket | E29: South West | F29: 13439.85 | G29: 15320.75 | H29: -1880.9 | I29: -12.28 | J29: 13044.1 | K29: 395.75 | L29: 103.03
A30: 2025-05 | B30: ST003 | C30: FreshMart South West 03 | D30: Supermarket | E30: South West | F30: 16651.96 | G30: 13439.85 | H30: 3212.11 | I30: 23.9 | J30: 17252.42 | K30: -600.46 | L30: 96.52
A31: 2025-06 | B31: ST003 | C31: FreshMart South West 03 | D31: Supermarket | E31: South West | F31: 15253.39 | G31: 16651.96 | H31: -1398.57 | I31: -8.4 | J31: 14385.61 | K31: 867.78 | L31: 106.03
A32: 2025-07 | B32: ST003 | C32: FreshMart South West 03 | D32: Supermarket | E32: South West | F32: 15277.25 | G32: 15253.39 | H32: 23.86 | I32: 0.16 | J32: 14763.29 | K32: 513.96 | L32: 103.48
A33: 2025-08 | B33: ST003 | C33: FreshMart South West 03 | D33: Supermarket | E33: South West | F33: 16769.81 | G33: 15277.25 | H33: 1492.56 | I33: 9.77 | J33: 16269.28 | K33: 500.53 | L33: 103.08
A34: 2025-09 | B34: ST003 | C34: FreshMart South West 03 | D34: Supermarket | E34: South West | F34: 15251.52 | G34: 16769.81 | H34: -1518.29 | I34: -9.05 | J34: 14744.58 | K34: 506.94 | L34: 103.44
A35: 2025-10 | B35: ST003 | C35: FreshMart South West 03 | D35: Supermarket | E35: South West | F35: 15939.26 | G35: 15251.52 | H35: 687.74 | I35: 4.51 | J35: 16294.17 | K35: -354.91 | L35: 97.82
A36: 2025-11 | B36: ST003 | C36: FreshMart South West 03 | D36: Supermarket | E36: South West | F36: 16750.6 | G36: 15939.26 | H36: 811.34 | I36: 5.09 | J36: 16822.98 | K36: -72.38 | L36: 99.57
A37: 2025-12 | B37: ST003 | C37: FreshMart South West 03 | D37: Supermarket | E37: South West | F37: 16656.28 | G37: 16750.6 | H37: -94.32 | I37: -0.56 | J37: 16281.6 | K37: 374.68 | L37: 102.3
A38: 2025-01 | B38: ST004 | C38: FreshMart Midlands 04 | D38: Supermarket | E38: Midlands | F38: 16209.96 | J38: 16280 | K38: -70.04 | L38: 99.57
A39: 2025-02 | B39: ST004 | C39: FreshMart Midlands 04 | D39: Supermarket | E39: Midlands | F39: 13923.1 | G39: 16209.96 | H39: -2286.86 | I39: -14.11 | J39: 13609.9 | K39: 313.2 | L39: 102.3
A40: 2025-03 | B40: ST004 | C40: FreshMart Midlands 04 | D40: Supermarket | E40: Midlands | F40: 16161.82 | G40: 13923.1 | H40: 2238.72 | I40: 16.08 | J40: 15685.92 | K40: 475.9 | L40: 103.03
...

Sheet tblCompanyMonthly
A1: month_year | B1: net_sales | C1: previous_month_sales | D1: sales_mom_pct | E1: transactions | F1: transactions_mom_pct | G1: units_sold | H1: avg_transaction_value | I1: atv_mom_pct | J1: units_per_transaction | K1: upt_mom_pct | L1: avg_selling_price | M1: asp_mom_pct | N1: sales_target | O1: sales_vs_target | P1: target_achievement_pct | Q1: ytd_net_sales | R1: ytd_sales_target | S1: ytd_sales_vs_target | T1: ytd_target_achievement_pct
A2: 2025-01 | B2: 347199.18 | E2: 8565 | G2: 43910 | H2: 40.54 | J2: 5.13 | L2: 7.91 | N2: 348047.53 | O2: -848.35 | P2: 99.76 | Q2: 347199.18 | R2: 348047.53 | S2: -848.35 | T2: 99.76
A3: 2025-02 | B3: 317297.71 | C3: 347199.18 | D3: -8.61 | E3: 7825 | F3: -8.64 | G3: 40268 | H3: 40.55 | I3: 0.02 | J3: 5.15 | K3: 0.39 | L3: 7.88 | M3: -0.38 | N3: 315138.36 | O3: 2159.35 | P3: 100.69 | Q3: 664496.89 | R3: 663185.89 | S3: 1311 | T3: 100.2
A4: 2025-03 | B4: 391277.02 | C4: 317297.71 | D4: 23.32 | E4: 9497 | F4: 21.37 | G4: 49001 | H4: 41.2 | I4: 1.6 | J4: 5.16 | K4: 0.19 | L4: 7.99 | M4: 1.4 | N4: 386010.06 | O4: 5266.96 | P4: 101.36 | Q4: 1055773.9 | R4: 1049195.9 | S4: 6577.96 | T4: 100.63
A5: 2025-04 | B5: 373482.58 | C5: 391277.02 | D5: -4.55 | E5: 9230 | F5: -2.81 | G5: 47037 | H5: 40.46 | I5: -1.8 | J5: 5.1 | K5: -1.16 | L5: 7.94 | M5: -0.63 | N5: 367268.6 | O5: 6213.98 | P5: 101.69 | Q5: 1429256.5 | R5: 1416464.6 | S5: 12791.94 | T5: 100.9
A6: 2025-05 | B6: 387910.67 | C6: 373482.58 | D6: 3.86 | E6: 9571 | F6: 3.69 | G6: 49169 | H6: 40.53 | I6: 0.17 | J6: 5.14 | K6: 0.78 | L6: 7.89 | M6: -0.63 | N6: 382254.6 | O6: 5656.07 | P6: 101.48 | Q6: 1817167.2 | R6: 1798719.1 | S6: 18448.01 | T6: 101.03
A7: 2025-06 | B7: 376894.58 | C7: 387910.67 | D7: -2.84 | E7: 9251 | F7: -3.34 | G7: 47633 | H7: 40.74 | I7: 0.52 | J7: 5.15 | K7: 0.19 | L7: 7.91 | M7: 0.25 | N7: 373757.12 | O7: 3137.46 | P7: 100.84 | Q7: 2194061.7 | R7: 2172476.3 | S7: 21585.47 | T7: 100.99
A8: 2025-07 | B8: 426209.48 | C8: 376894.58 | D8: 13.08 | E8: 10268 | F8: 10.99 | G8: 53027 | H8: 41.51 | I8: 1.89 | J8: 5.16 | K8: 0.19 | L8: 8.04 | M8: 1.64 | N8: 424003.06 | O8: 2206.42 | P8: 100.52 | Q8: 2620271.2 | R8: 2596479.3 | S8: 23791.89 | T8: 100.92
A9: 2025-08 | B9: 441528.02 | C9: 426209.48 | D9: 3.59 | E9: 10728 | F9: 4.48 | G9: 55148 | H9: 41.16 | I9: -0.84 | J9: 5.14 | K9: -0.39 | L9: 8.01 | M9: -0.37 | N9: 440642.39 | O9: 885.63 | P9: 100.2 | Q9: 3061799.2 | R9: 3037121.7 | S9: 24677.52 | T9: 100.81
A10: 2025-09 | B10: 406552.16 | C10: 441528.02 | D10: -7.92 | E10: 9926 | F10: -7.48 | G10: 51055 | H10: 40.96 | I10: -0.49 | J10: 5.14 | K10: 0 | L10: 7.96 | M10: -0.62 | N10: 408079.57 | O10: -1527.41 | P10: 99.63 | Q10: 3468351.4 | R10: 3445201.3 | S10: 23150.11 | T10: 100.67
A11: 2025-10 | B11: 426232.46 | C11: 406552.16 | D11: 4.84 | E11: 10444 | F11: 5.22 | G11: 53471 | H11: 40.81 | I11: -0.37 | J11: 5.12 | K11: -0.39 | L11: 7.97 | M11: 0.13 | N11: 426573.75 | O11: -341.29 | P11: 99.92 | Q11: 3894583.9 | R11: 3871775 | S11: 22808.82 | T11: 100.59
A12: 2025-11 | B12: 416804.93 | C12: 426232.46 | D12: -2.21 | E12: 10110 | F12: -3.2 | G12: 52044 | H12: 41.23 | I12: 1.03 | J12: 5.15 | K12: 0.59 | L12: 8.01 | M12: 0.5 | N12: 413772.79 | O12: 3032.14 | P12: 100.73 | Q12: 4311388.8 | R12: 4285547.8 | S12: 25840.96 | T12: 100.6
A13: 2025-12 | B13: 433925.11 | C13: 416804.93 | D13: 4.11 | E13: 10404 | F13: 2.91 | G13: 53757 | H13: 41.71 | I13: 1.16 | J13: 5.17 | K13: 0.39 | L13: 8.07 | M13: 0.75 | N13: 426923.77 | O13: 7001.34 | P13: 101.64 | Q13: 4745313.9 | R13: 4712471.6 | S13: 32842.3 | T13: 100.7

Sheet Data
A1: Reporting Months
A2: 45658
A3: 45689
A4: 45717
A5: 45748
A6: 45778
A7: 45809
A8: 45839
A9: 45870
A10: 45901
A11: 45931
A12: 45962
A13: 45992
